<?xml version="1.0"?>
<robot name="box_bot">
    <material name="red">
        <color rgba="1.0 0.0 0.0 1"/>
    </material>

    <material name="green_light">
        <color rgba="0.0 1.0 0.0 1"/>
    </material>

    <material name="green_dark">
        <color rgba="0.0 0.5 0.0 1"/>
    </material>

    <material name="blue">
        <color rgba="0.0 0.0 1.0 1"/>
    </material>

    <material name="black">
        <color rgba="0.0 0.0 0.0 1"/>
    </material>

    <material name="white">
        <color rgba="1.0 1.0 1.0 1"/>
    </material>

    <link name="base_link">
    </link>

    <link name="chassis">
        <visual>
            <geometry>
                <box size="0.1 0.1 0.1"/>
            </geometry>
            <material name="blue"/>
        </visual>
    </link>

    <joint name="base_link_joint" type="fixed">
        <origin xyz="0 0 0" rpy="0 0 0"/>
        <parent link="base_link"/>
        <child link="chassis"/>
    </joint>

    <!-- Left wheel -->
    <link name="left_wheel">
        <visual>
            <origin xyz="0 0 0" rpy="0 1.5707 1.5707"/>
            <geometry>
                <cylinder length="0.001" radius="0.035"/>
            </geometry>
            <material name="black"/>
        </visual>
    </link>

    <joint name="left_wheel" type="continuous">
        <origin xyz="0.0 0.05 -0.025" rpy="0 0 0"/>
        <parent link="chassis"/>
        <child link="left_wheel"/>
        <axis xyz="0 1 0" rpy="0 0 0"/>
        <limit effort="10000" velocity="1000"/>
        <joint_properties damping="1.0" friction="1.0"/>
    </joint>

    <!-- Right wheel -->
    <link name="right_wheel">
        <visual>
            <origin xyz="0 0 0" rpy="0 1.5707 1.5707"/>
            <geometry>
                <cylinder length="0.001" radius="0.035"/>
            </geometry>
            <material name="black"/>
        </visual>
    </link>

    <joint name="right_wheel" type="continuous">
        <origin xyz="0.0 -0.05 -0.025" rpy="0 0 0"/>
        <parent link="chassis"/>
        <child link="right_wheel"/>
        <axis xyz="0 1 0" rpy="0 0 0"/>
        <limit effort="10000" velocity="1000"/>
        <joint_properties damping="1.0" friction="1.0"/>
    </joint>

</robot>